Workbook

Sheet Dashboard
B2: Inventory & Supply Chain Optimization Dashboard
B3: Sample data — see 'Read Me' tab. All KPI tiles and charts below are live formulas.
B5: Total SKUs | E5: Total Inventory Value | H5: Items to Reorder Now | K5: Avg. Days of Supply
B6: =COUNTA(Inventory!$A$2:$A$49) -> 48 | E6: =SUM(Inventory!$N$2:$N$49) -> 1810924.7 | H6: =COUNTIF(Inventory!$P$2:$P$49,"Reorder Now") -> 12 | K6: =AVERAGE(Inventory!$O$2:$O$49) -> 42.40856
B9: Active Suppliers | E9: Avg. Supplier On-Time % | H9: Total PO Spend | K9: Pending Purchase Orders
B10: =COUNTA(Suppliers!$A$2:$A$9) -> 8 | E10: =AVERAGE(Suppliers!$J$2:$J$9) -> 0.65694444 | H10: =SUM('Purchase Orders'!$K$2:$K$91) -> 4776655.8 | K10: =COUNTIF('Purchase Orders'!$I$2:$I$91,"Pending") -> 10
B47: Top Items Needing Reorder (lowest days of supply)
B48: SKU | C48: Product Name | D48: Warehouse | E48: Current Stock | F48: Reorder Point | G48: Days of Supply | H48: Supplier
B49: =IFERROR(INDEX(Inventory!$A$2:$A$49,MATCH(SMALL(Inventory!$R$2:$R$49,1),Inventory!$R$2:$R$49,0)),"") -> SKU-1011 | C49: =IFERROR(INDEX(Inventory!$B$2:$B$49,MATCH(SMALL(Inventory!$R$2:$R$49,1),Inventory!$R$2:$R$49,0)),"") -> Adhesive Tube C | D49: =IFERROR(INDEX(Inventory!$D$2:$D$49,MATCH(SMALL(Inventory!$R$2:$R$49,1),Inventory!$R$2:$R$49,0)),"") -> WH-East | E49: =IFERROR(INDEX(Inventory!$G$2:$G$49,MATCH(SMALL(Inventory!$R$2:$R$49,1),Inventory!$R$2:$R$49,0)),"") -> 1 | F49: =IFERROR(INDEX(Inventory!$H$2:$H$49,MATCH(SMALL(Inventory!$R$2:$R$49,1),Inventory!$R$2:$R$49,0)),"") -> 136 | G49: =IFERROR(ROUND(INDEX(Inventory!$O$2:$O$49,MATCH(SMALL(Inventory!$R$2:$R$49,1),Inventory!$R$2:$R$49,0)),1),"") -> 0.1 | H49: =IFERROR(INDEX(Inventory!$Q$2:$Q$49,MATCH(SMALL(Inventory!$R$2:$R$49,1),Inventory!$R$2:$R$49,0)),"") -> Global Pack Solutions
B50: =IFERROR(INDEX(Inventory!$A$2:$A$49,MATCH(SMALL(Inventory!$R$2:$R$49,2),Inventory!$R$2:$R$49,0)),"") -> SKU-1046 | C50: =IFERROR(INDEX(Inventory!$B$2:$B$49,MATCH(SMALL(Inventory!$R$2:$R$49,2),Inventory!$R$2:$R$49,0)),"") -> Hinge Assembly Standard | D50: =IFERROR(INDEX(Inventory!$D$2:$D$49,MATCH(SMALL(Inventory!$R$2:$R$49,2),Inventory!$R$2:$R$49,0)),"") -> WH-South | E50: =IFERROR(INDEX(Inventory!$G$2:$G$49,MATCH(SMALL(Inventory!$R$2:$R$49,2),Inventory!$R$2:$R$49,0)),"") -> 14 | F50: =IFERROR(INDEX(Inventory!$H$2:$H$49,MATCH(SMALL(Inventory!$R$2:$R$49,2),Inventory!$R$2:$R$49,0)),"") -> 144 | G50: =IFERROR(ROUND(INDEX(Inventory!$O$2:$O$49,MATCH(SMALL(Inventory!$R$2:$R$49,2),Inventory!$R$2:$R$49,0)),1),"") -> 1.3 | H50: =IFERROR(INDEX(Inventory!$Q$2:$Q$49,MATCH(SMALL(Inventory!$R$2:$R$49,2),Inventory!$R$2:$R$49,0)),"") -> Prime Consumables Corp.
B51: =IFERROR(INDEX(Inventory!$A$2:$A$49,MATCH(SMALL(Inventory!$R$2:$R$49,3),Inventory!$R$2:$R$49,0)),"") -> SKU-1029 | C51: =IFERROR(INDEX(Inventory!$B$2:$B$49,MATCH(SMALL(Inventory!$R$2:$R$49,3),Inventory!$R$2:$R$49,0)),"") -> Lubricant Can C | D51: =IFERROR(INDEX(Inventory!$D$2:$D$49,MATCH(SMALL(Inventory!$R$2:$R$49,3),Inventory!$R$2:$R$49,0)),"") -> WH-South | E51: =IFERROR(INDEX(Inventory!$G$2:$G$49,MATCH(SMALL(Inventory!$R$2:$R$49,3),Inventory!$R$2:$R$49,0)),"") -> 20 | F51: =IFERROR(INDEX(Inventory!$H$2:$H$49,MATCH(SMALL(Inventory!$R$2:$R$49,3),Inventory!$R$2:$R$49,0)),"") -> 113 | G51: =IFERROR(ROUND(INDEX(Inventory!$O$2:$O$49,MATCH(SMALL(Inventory!$R$2:$R$49,3),Inventory!$R$2:$R$49,0)),1),"") -> 2 | H51: =IFERROR(INDEX(Inventory!$Q$2:$Q$49,MATCH(SMALL(Inventory!$R$2:$R$49,3),Inventory!$R$2:$R$49,0)),"") -> Sterling Hardware Inc.
B52: =IFERROR(INDEX(Inventory!$A$2:$A$49,MATCH(SMALL(Inventory!$R$2:$R$49,4),Inventory!$R$2:$R$49,0)),"") -> SKU-1034 | C52: =IFERROR(INDEX(Inventory!$B$2:$B$49,MATCH(SMALL(Inventory!$R$2:$R$49,4),Inventory!$R$2:$R$49,0)),"") -> Ball Bearing X | D52: =IFERROR(INDEX(Inventory!$D$2:$D$49,MATCH(SMALL(Inventory!$R$2:$R$49,4),Inventory!$R$2:$R$49,0)),"") -> WH-North | E52: =IFERROR(INDEX(Inventory!$G$2:$G$49,MATCH(SMALL(Inventory!$R$2:$R$49,4),Inventory!$R$2:$R$49,0)),"") -> 22 | F52: =IFERROR(INDEX(Inventory!$H$2:$H$49,MATCH(SMALL(Inventory!$R$2:$R$49,4),Inventory!$R$2:$R$49,0)),"") -> 85 | G52: =IFERROR(ROUND(INDEX(Inventory!$O$2:$O$49,MATCH(SMALL(Inventory!$R$2:$R$49,4),Inventory!$R$2:$R$49,0)),1),"") -> 2.8 | H52: =IFERROR(INDEX(Inventory!$Q$2:$Q$49,MATCH(SMALL(Inventory!$R$2:$R$49,4),Inventory!$R$2:$R$49,0)),"") -> Apex Components Ltd.
B53: =IFERROR(INDEX(Inventory!$A$2:$A$49,MATCH(SMALL(Inventory!$R$2:$R$49,5),Inventory!$R$2:$R$49,0)),"") -> SKU-1004 | C53: =IFERROR(INDEX(Inventory!$B$2:$B$49,MATCH(SMALL(Inventory!$R$2:$R$49,5),Inventory!$R$2:$R$49,0)),"") -> Ball Bearing A | D53: =IFERROR(INDEX(Inventory!$D$2:$D$49,MATCH(SMALL(Inventory!$R$2:$R$49,5),Inventory!$R$2:$R$49,0)),"") -> WH-Central | E53: =IFERROR(INDEX(Inventory!$G$2:$G$49,MATCH(SMALL(Inventory!$R$2:$R$49,5),Inventory!$R$2:$R$49,0)),"") -> 40 | F53: =IFERROR(INDEX(Inventory!$H$2:$H$49,MATCH(SMALL(Inventory!$R$2:$R$49,5),Inventory!$R$2:$R$49,0)),"") -> 116 | G53: =IFERROR(ROUND(INDEX(Inventory!$O$2:$O$49,MATCH(SMALL(Inventory!$R$2:$R$49,5),Inventory!$R$2:$R$49,0)),1),"") -> 4.5 | H53: =IFERROR(INDEX(Inventory!$Q$2:$Q$49,MATCH(SMALL(Inventory!$R$2:$R$49,5),Inventory!$R$2:$R$49,0)),"") -> Meridian Parts Group
B54: =IFERROR(INDEX(Inventory!$A$2:$A$49,MATCH(SMALL(Inventory!$R$2:$R$49,6),Inventory!$R$2:$R$49,0)),"") -> SKU-1009 | C54: =IFERROR(INDEX(Inventory!$B$2:$B$49,MATCH(SMALL(Inventory!$R$2:$R$49,6),Inventory!$R$2:$R$49,0)),"") -> Carton Tape Pro | D54: =IFERROR(INDEX(Inventory!$D$2:$D$49,MATCH(SMALL(Inventory!$R$2:$R$49,6),Inventory!$R$2:$R$49,0)),"") -> WH-Central | E54: =IFERROR(INDEX(Inventory!$G$2:$G$49,MATCH(SMALL(Inventory!$R$2:$R$49,6),Inventory!$R$2:$R$49,0)),"") -> 70 | F54: =IFERROR(INDEX(Inventory!$H$2:$H$49,MATCH(SMALL(Inventory!$R$2:$R$49,6),Inventory!$R$2:$R$49,0)),"") -> 76 | G54: =IFERROR(ROUND(INDEX(Inventory!$O$2:$O$49,MATCH(SMALL(Inventory!$R$2:$R$49,6),Inventory!$R$2:$R$49,0)),1),"") -> 6.1 | H54: =IFERROR(INDEX(Inventory!$Q$2:$Q$49,MATCH(SMALL(Inventory!$R$2:$R$49,6),Inventory!$R$2:$R$49,0)),"") -> Northline Materials Co.
B55: =IFERROR(INDEX(Inventory!$A$2:$A$49,MATCH(SMALL(Inventory!$R$2:$R$49,7),Inventory!$R$2:$R$49,0)),"") -> SKU-1008 | C55: =IFERROR(INDEX(Inventory!$B$2:$B$49,MATCH(SMALL(Inventory!$R$2:$R$49,7),Inventory!$R$2:$R$49,0)),"") -> Copper Wire Coil B | D55: =IFERROR(INDEX(Inventory!$D$2:$D$49,MATCH(SMALL(Inventory!$R$2:$R$49,7),Inventory!$R$2:$R$49,0)),"") -> WH-Central | E55: =IFERROR(INDEX(Inventory!$G$2:$G$49,MATCH(SMALL(Inventory!$R$2:$R$49,7),Inventory!$R$2:$R$49,0)),"") -> 73 | F55: =IFERROR(INDEX(Inventory!$H$2:$H$49,MATCH(SMALL(Inventory!$R$2:$R$49,7),Inventory!$R$2:$R$49,0)),"") -> 137 | G55: =IFERROR(ROUND(INDEX(Inventory!$O$2:$O$49,MATCH(SMALL(Inventory!$R$2:$R$49,7),Inventory!$R$2:$R$49,0)),1),"") -> 6.5 | H55: =IFERROR(INDEX(Inventory!$Q$2:$Q$49,MATCH(SMALL(Inventory!$R$2:$R$49,7),Inventory!$R$2:$R$49,0)),"") -> Sterling Hardware Inc.
B56: =IFERROR(INDEX(Inventory!$A$2:$A$49,MATCH(SMALL(Inventory!$R$2:$R$49,8),Inventory!$R$2:$R$49,0)),"") -> SKU-1018 | C56: =IFERROR(INDEX(Inventory!$B$2:$B$49,MATCH(SMALL(Inventory!$R$2:$R$49,8),Inventory!$R$2:$R$49,0)),"") -> Drive Belt B | D56: =IFERROR(INDEX(Inventory!$D$2:$D$49,MATCH(SMALL(Inventory!$R$2:$R$49,8),Inventory!$R$2:$R$49,0)),"") -> WH-South | E56: =IFERROR(INDEX(Inventory!$G$2:$G$49,MATCH(SMALL(Inventory!$R$2:$R$49,8),Inventory!$R$2:$R$49,0)),"") -> 93 | F56: =IFERROR(INDEX(Inventory!$H$2:$H$49,MATCH(SMALL(Inventory!$R$2:$R$49,8),Inventory!$R$2:$R$49,0)),"") -> 128 | G56: =IFERROR(ROUND(INDEX(Inventory!$O$2:$O$49,MATCH(SMALL(Inventory!$R$2:$R$49,8),Inventory!$R$2:$R$49,0)),1),"") -> 7 | H56: =IFERROR(INDEX(Inventory!$Q$2:$Q$49,MATCH(SMALL(Inventory!$R$2:$R$49,8),Inventory!$R$2:$R$49,0)),"") -> Sterling Hardware Inc.
B57: =IFERROR(INDEX(Inventory!$A$2:$A$49,MATCH(SMALL(Inventory!$R$2:$R$49,9),Inventory!$R$2:$R$49,0)),"") -> SKU-1003 | C57: =IFERROR(INDEX(Inventory!$B$2:$B$49,MATCH(SMALL(Inventory!$R$2:$R$49,9),Inventory!$R$2:$R$49,0)),"") -> Corrugated Box B | D57: =IFERROR(INDEX(Inventory!$D$2:$D$49,MATCH(SMALL(Inventory!$R$2:$R$49,9),Inventory!$R$2:$R$49,0)),"") -> WH-Central | E57: =IFERROR(INDEX(Inventory!$G$2:$G$49,MATCH(SMALL(Inventory!$R$2:$R$49,9),Inventory!$R$2:$R$49,0)),"") -> 52 | F57: =IFERROR(INDEX(Inventory!$H$2:$H$49,MATCH(SMALL(Inventory!$R$2:$R$49,9),Inventory!$R$2:$R$49,0)),"") -> 106 | G57: =IFERROR(ROUND(INDEX(Inventory!$O$2:$O$49,MATCH(SMALL(Inventory!$R$2:$R$49,9),Inventory!$R$2:$R$49,0)),1),"") -> 9.1 | H57: =IFERROR(INDEX(Inventory!$Q$2:$Q$49,MATCH(SMALL(Inventory!$R$2:$R$49,9),Inventory!$R$2:$R$49,0)),"") -> Northline Materials Co.
B58: =IFERROR(INDEX(Inventory!$A$2:$A$49,MATCH(SMALL(Inventory!$R$2:$R$49,10),Inventory!$R$2:$R$49,0)),"") -> SKU-1024 | C58: =IFERROR(INDEX(Inventory!$B$2:$B$49,MATCH(SMALL(Inventory!$R$2:$R$49,10),Inventory!$R$2:$R$49,0)),"") -> Hydraulic Valve A | D58: =IFERROR(INDEX(Inventory!$D$2:$D$49,MATCH(SMALL(Inventory!$R$2:$R$49,10),Inventory!$R$2:$R$49,0)),"") -> WH-North | E58: =IFERROR(INDEX(Inventory!$G$2:$G$49,MATCH(SMALL(Inventory!$R$2:$R$49,10),Inventory!$R$2:$R$49,0)),"") -> 37 | F58: =IFERROR(INDEX(Inventory!$H$2:$H$49,MATCH(SMALL(Inventory!$R$2:$R$49,10),Inventory!$R$2:$R$49,0)),"") -> 45 | G58: =IFERROR(ROUND(INDEX(Inventory!$O$2:$O$49,MATCH(SMALL(Inventory!$R$2:$R$49,10),Inventory!$R$2:$R$49,0)),1),"") -> 15.4 | H58: =IFERROR(INDEX(Inventory!$Q$2:$Q$49,MATCH(SMALL(Inventory!$R$2:$R$49,10),Inventory!$R$2:$R$49,0)),"") -> Vertex Industrial Supply

Sheet Read Me
B2: Inventory & Supply Chain Optimization Dashboard
B3: Sample workbook — generated with realistic illustrative data for demonstration purposes.
B5: Purpose | C5: Tracks inventory health, reorder needs, and supplier / purchase-order performance across 4 warehouses.
B7: Data source | C7: All figures on the Inventory, Suppliers, and Purchase Orders tabs are SAMPLE DATA generated for this workbook (seeded random generator) — not real company data. Replace with your own data to make this live.
B9: How to use | C9: Edit the yellow-highlighted input cells on the Inventory, Suppliers, and Purchase Orders tabs. Every KPI and chart on the Dashboard tab recalculates automatically via formulas.
B11: Import into Power BI | C11: Open Power BI Desktop -> Get Data -> Excel Workbook -> select this file -> load the Inventory, Suppliers, and Purchase Orders tables -> build relationships on SKU and Supplier ID -> recreate the visuals from the Dashboard tab (or use them as a starting reference).
B13: Key formulas | C13: Stock Status = IF current stock <= reorder point -> 'Reorder Now'; Days of Supply = current stock / average daily usage; On-Time Flag (POs) = actual delivery <= expected delivery.
B15: Refresh | C15: Recalculates automatically in Excel. If values show as 0 after editing in some non-Excel viewers, open in Excel/LibreOffice once to force a recalculation.
B18: Cell color legend
B19: Editable input
B20: Formula (do not overwrite)

Sheet Suppliers
A1: Supplier ID | B1: Supplier Name | C1: Location | D1: Avg Lead Time (days) | E1: On-Time Delivery % | F1: Quality Rating (1-5) | G1: Active Since | H1: Total POs | I1: Total Spend ($) | J1: Actual On-Time % (from POs)
A2: SUP-001 | B2: Apex Components Ltd. | C2: Chennai, IN | D2: 28 | E2: 0.866 | F2: 5 | G2: 43942 | H2: =COUNTIF('Purchase Orders'!$C$2:$C$91,A2) -> 5 | I2: =SUMIFS('Purchase Orders'!$K$2:$K$91,'Purchase Orders'!$C$2:$C$91,A2) -> 298024.36 | J2: =IFERROR(AVERAGEIFS('Purchase Orders'!$M$2:$M$91,'Purchase Orders'!$C$2:$C$91,A2),"n/a") -> 0.8
A3: SUP-002 | B3: Northline Materials Co. | C3: Pune, IN | D3: 7 | E3: 0.931 | F3: 4.4 | G3: 45299 | H3: =COUNTIF('Purchase Orders'!$C$2:$C$91,A3) -> 15 | I3: =SUMIFS('Purchase Orders'!$K$2:$K$91,'Purchase Orders'!$C$2:$C$91,A3) -> 590717.51 | J3: =IFERROR(AVERAGEIFS('Purchase Orders'!$M$2:$M$91,'Purchase Orders'!$C$2:$C$91,A3),"n/a") -> 0.66666667
A4: SUP-003 | B4: Global Pack Solutions | C4: Ahmedabad, IN | D4: 11 | E4: 0.947 | F4: 4.3 | G4: 43540 | H4: =COUNTIF('Purchase Orders'!$C$2:$C$91,A4) -> 9 | I4: =SUMIFS('Purchase Orders'!$K$2:$K$91,'Purchase Orders'!$C$2:$C$91,A4) -> 1080550.3 | J4: =IFERROR(AVERAGEIFS('Purchase Orders'!$M$2:$M$91,'Purchase Orders'!$C$2:$C$91,A4),"n/a") -> 0.88888889
A5: SUP-004 | B5: Sterling Hardware Inc. | C5: Delhi, IN | D5: 26 | E5: 0.751 | F5: 4.9 | G5: 44539 | H5: =COUNTIF('Purchase Orders'!$C$2:$C$91,A5) -> 17 | I5: =SUMIFS('Purchase Orders'!$K$2:$K$91,'Purchase Orders'!$C$2:$C$91,A5) -> 409604.89 | J5: =IFERROR(AVERAGEIFS('Purchase Orders'!$M$2:$M$91,'Purchase Orders'!$C$2:$C$91,A5),"n/a") -> 0.53333333
A6: SUP-005 | B6: Vertex Industrial Supply | C6: Bengaluru, IN | D6: 29 | E6: 0.82 | F6: 4.3 | G6: 45264 | H6: =COUNTIF('Purchase Orders'!$C$2:$C$91,A6) -> 9 | I6: =SUMIFS('Purchase Orders'!$K$2:$K$91,'Purchase Orders'!$C$2:$C$91,A6) -> 555704.65 | J6: =IFERROR(AVERAGEIFS('Purchase Orders'!$M$2:$M$91,'Purchase Orders'!$C$2:$C$91,A6),"n/a") -> 0.75
A7: SUP-006 | B7: Meridian Parts Group | C7: Hyderabad, IN | D7: 29 | E7: 0.941 | F7: 4.9 | G7: 43374 | H7: =COUNTIF('Purchase Orders'!$C$2:$C$91,A7) -> 21 | I7: =SUMIFS('Purchase Orders'!$K$2:$K$91,'Purchase Orders'!$C$2:$C$91,A7) -> 1199685.6 | J7: =IFERROR(AVERAGEIFS('Purchase Orders'!$M$2:$M$91,'Purchase Orders'!$C$2:$C$91,A7),"n/a") -> 0.55
A8: SUP-007 | B8: Prime Consumables Corp. | C8: Mumbai, IN | D8: 14 | E8: 0.875 | F8: 4.8 | G8: 44400 | H8: =COUNTIF('Purchase Orders'!$C$2:$C$91,A8) -> 8 | I8: =SUMIFS('Purchase Orders'!$K$2:$K$91,'Purchase Orders'!$C$2:$C$91,A8) -> 374040.15 | J8: =IFERROR(AVERAGEIFS('Purchase Orders'!$M$2:$M$91,'Purchase Orders'!$C$2:$C$91,A8),"n/a") -> 0.4
A9: SUP-008 | B9: Horizon Machinery Traders | C9: Coimbatore, IN | D9: 11 | E9: 0.741 | F9: 4.4 | G9: 45020 | H9: =COUNTIF('Purchase Orders'!$C$2:$C$91,A9) -> 6 | I9: =SUMIFS('Purchase Orders'!$K$2:$K$91,'Purchase Orders'!$C$2:$C$91,A9) -> 268328.25 | J9: =IFERROR(AVERAGEIFS('Purchase Orders'!$M$2:$M$91,'Purchase Orders'!$C$2:$C$91,A9),"n/a") -> 0.66666667

Sheet Inventory
A1: SKU | B1: Product Name | C1: Category | D1: Warehouse | E1: Unit Cost ($) | F1: Unit Price ($) | G1: Current Stock | H1: Reorder Point | I1: Reorder Qty | J1: Lead Time (days) | K1: Supplier ID | L1: Avg Daily Usage | M1: Last Restock Date | N1: Inventory Value ($) | O1: Days of Supply | P1: Stock Status | Q1: Supplier Name | R1: Reorder Sort Key
A2: SKU-1001 | B2: Cable Harness A | C2: Electronics | D2: WH-North | E2: 334.21 | F2: 466.53 | G2: 377 | H2: 55 | I2: 152 | J2: 37 | K2: SUP-002 | L2: 9.1 | M2: 46113 | N2: =G2*E2 -> 125997.17 | O2: =IFERROR(G2/L2,"n/a") -> 41.428571 | P2: =IF(G2<=H2,"Reorder Now",IF(AND(ISNUMBER(O2),O2<14),"Low - Watch","OK")) -> OK | Q2: =IFERROR(INDEX(Suppliers!$B$2:$B$9,MATCH(K2,Suppliers!$A$2:$A$9,0)),"Unknown") -> Northline Materials Co. | R2: =IF(P2="Reorder Now",O2+ROW()/100000,"")
A3: SKU-1002 | B3: Steel Sheet B | C3: Raw Materials | D3: WH-South | E3: 228.4 | F3: 278.93 | G3: 366 | H3: 70 | I3: 432 | J3: 37 | K3: SUP-007 | L3: 3.7 | M3: 46243 | N3: =G3*E3 -> 83594.4 | O3: =IFERROR(G3/L3,"n/a") -> 98.918919 | P3: =IF(G3<=H3,"Reorder Now",IF(AND(ISNUMBER(O3),O3<14),"Low - Watch","OK")) -> OK | Q3: =IFERROR(INDEX(Suppliers!$B$2:$B$9,MATCH(K3,Suppliers!$A$2:$A$9,0)),"Unknown") -> Prime Consumables Corp. | R3: =IF(P3="Reorder Now",O3+ROW()/100000,"")
A4: SKU-1003 | B4: Corrugated Box B | C4: Packaging | D4: WH-Central | E4: 154.43 | F4: 204.52 | G4: 52 | H4: 106 | I4: 147 | J4: 27 | K4: SUP-002 | L4: 5.7 | M4: 46193 | N4: =G4*E4 -> 8030.36 | O4: =IFERROR(G4/L4,"n/a") -> 9.122807 | P4: =IF(G4<=H4,"Reorder Now",IF(AND(ISNUMBER(O4),O4<14),"Low - Watch","OK")) -> Reorder Now | Q4: =IFERROR(INDEX(Suppliers!$B$2:$B$9,MATCH(K4,Suppliers!$A$2:$A$9,0)),"Unknown") -> Northline Materials Co. | R4: =IF(P4="Reorder Now",O4+ROW()/100000,"") -> 9.122847
A5: SKU-1004 | B5: Ball Bearing A | C5: Hardware | D5: WH-Central | E5: 242.23 | F5: 479.25 | G5: 40 | H5: 116 | I5: 382 | J5: 21 | K5: SUP-006 | L5: 8.9 | M5: 46114 | N5: =G5*E5 -> 9689.2 | O5: =IFERROR(G5/L5,"n/a") -> 4.494382 | P5: =IF(G5<=H5,"Reorder Now",IF(AND(ISNUMBER(O5),O5<14),"Low - Watch","OK")) -> Reorder Now | Q5: =IFERROR(INDEX(Suppliers!$B$2:$B$9,MATCH(K5,Suppliers!$A$2:$A$9,0)),"Unknown") -> Meridian Parts Group | R5: =IF(P5="Reorder Now",O5+ROW()/100000,"") -> 4.494432
A6: SKU-1005 | B6: Sandpaper Sheet B | C6: Consumables | D6: WH-East | E6: 443.38 | F6: 835.44 | G6: 194 | H6: 45 | I6: 242 | J6: 32 | K6: SUP-006 | L6: 2.9 | M6: 46180 | N6: =G6*E6 -> 86015.72 | O6: =IFERROR(G6/L6,"n/a") -> 66.896552 | P6: =IF(G6<=H6,"Reorder Now",IF(AND(ISNUMBER(O6),O6<14),"Low - Watch","OK")) -> OK | Q6: =IFERROR(INDEX(Suppliers!$B$2:$B$9,MATCH(K6,Suppliers!$A$2:$A$9,0)),"Unknown") -> Meridian Parts Group | R6: =IF(P6="Reorder Now",O6+ROW()/100000,"")
A7: SKU-1006 | B7: Conveyor Roller C | C7: Machinery Parts | D7: WH-North | E7: 274.89 | F7: 367.5 | G7: 83 | H7: 82 | I7: 336 | J7: 27 | K7: SUP-005 | L7: 14.8 | M7: 46242 | N7: =G7*E7 -> 22815.87 | O7: =IFERROR(G7/L7,"n/a") -> 5.6081081 | P7: =IF(G7<=H7,"Reorder Now",IF(AND(ISNUMBER(O7),O7<14),"Low - Watch","OK")) -> Low - Watch | Q7: =IFERROR(INDEX(Suppliers!$B$2:$B$9,MATCH(K7,Suppliers!$A$2:$A$9,0)),"Unknown") -> Vertex Industrial Supply | R7: =IF(P7="Reorder Now",O7+ROW()/100000,"")
A8: SKU-1007 | B8: Cable Harness C | C8: Electronics | D8: WH-North | E8: 104.61 | F8: 128.22 | G8: 205 | H8: 100 | I8: 237 | J8: 7 | K8: SUP-004 | L8: 13.7 | M8: 46257 | N8: =G8*E8 -> 21445.05 | O8: =IFERROR(G8/L8,"n/a") -> 14.963504 | P8: =IF(G8<=H8,"Reorder Now",IF(AND(ISNUMBER(O8),O8<14),"Low - Watch","OK")) -> OK | Q8: =IFERROR(INDEX(Suppliers!$B$2:$B$9,MATCH(K8,Suppliers!$A$2:$A$9,0)),"Unknown") -> Sterling Hardware Inc. | R8: =IF(P8="Reorder Now",O8+ROW()/100000,"")
A9: SKU-1008 | B9: Copper Wire Coil B | C9: Raw Materials | D9: WH-Central | E9: 179.24 | F9: 346.23 | G9: 73 | H9: 137 | I9: 235 | J9: 11 | K9: SUP-004 | L9: 11.3 | M9: 46243 | N9: =G9*E9 -> 13084.52 | O9: =IFERROR(G9/L9,"n/a") -> 6.460177 | P9: =IF(G9<=H9,"Reorder Now",IF(AND(ISNUMBER(O9),O9<14),"Low - Watch","OK")) -> Reorder Now | Q9: =IFERROR(INDEX(Suppliers!$B$2:$B$9,MATCH(K9,Suppliers!$A$2:$A$9,0)),"Unknown") -> Sterling Hardware Inc. | R9: =IF(P9="Reorder Now",O9+ROW()/100000,"") -> 6.460267
A10: SKU-1009 | B10: Carton Tape Pro | C10: Packaging | D10: WH-Central | E10: 404.22 | F10: 614.22 | G10: 70 | H10: 76 | I10: 360 | J10: 34 | K10: SUP-002 | L10: 11.5 | M10: 46117 | N10: =G10*E10 -> 28295.4 | O10: =IFERROR(G10/L10,"n/a") -> 6.0869565 | P10: =IF(G10<=H10,"Reorder Now",IF(AND(ISNUMBER(O10),O10<14),"Low - Watch","OK")) -> Reorder Now | Q10: =IFERROR(INDEX(Suppliers!$B$2:$B$9,MATCH(K10,Suppliers!$A$2:$A$9,0)),"Unknown") -> Northline Materials Co. | R10: =IF(P10="Reorder Now",O10+ROW()/100000,"") -> 6.0870565
A11: SKU-1010 | B11: Hinge Assembly B | C11: Hardware | D11: WH-Central | E11: 269.19 | F11: 405.89 | G11: 270 | H11: 139 | I11: 228 | J11: 38 | K11: SUP-001 | L11: 10.4 | M11: 46134 | N11: =G11*E11 -> 72681.3 | O11: =IFERROR(G11/L11,"n/a") -> 25.961538 | P11: =IF(G11<=H11,"Reorder Now",IF(AND(ISNUMBER(O11),O11<14),"Low - Watch","OK")) -> OK | Q11: =IFERROR(INDEX(Suppliers!$B$2:$B$9,MATCH(K11,Suppliers!$A$2:$A$9,0)),"Unknown") -> Apex Components Ltd. | R11: =IF(P11="Reorder Now",O11+ROW()/100000,"")
A12: SKU-1011 | B12: Adhesive Tube C | C12: Consumables | D12: WH-East | E12: 51.98 | F12: 80.46 | G12: 1 | H12: 136 | I12: 469 | J12: 19 | K12: SUP-003 | L12: 7.9 | M12: 46140 | N12: =G12*E12 -> 51.98 | O12: =IFERROR(G12/L12,"n/a") -> 0.12658228 | P12: =IF(G12<=H12,"Reorder Now",IF(AND(ISNUMBER(O12),O12<14),"Low - Watch","OK")) -> Reorder Now | Q12: =IFERROR(INDEX(Suppliers!$B$2:$B$9,MATCH(K12,Suppliers!$A$2:$A$9,0)),"Unknown") -> Global Pack Solutions | R12: =IF(P12="Reorder Now",O12+ROW()/100000,"") -> 0.12670228
A13: SKU-1012 | B13: Conveyor Roller C | C13: Machinery Parts | D13: WH-South | E13: 70.47 | F13: 127.55 | G13: 306 | H13: 20 | I13: 265 | J13: 34 | K13: SUP-001 | L13: 2.1 | M13: 46200 | N13: =G13*E13 -> 21563.82 | O13: =IFERROR(G13/L13,"n/a") -> 145.71429 | P13: =IF(G13<=H13,"Reorder Now",IF(AND(ISNUMBER(O13),O13<14),"Low - Watch","OK")) -> OK | Q13: =IFERROR(INDEX(Suppliers!$B$2:$B$9,MATCH(K13,Suppliers!$A$2:$A$9,0)),"Unknown") -> Apex Components Ltd. | R13: =IF(P13="Reorder Now",O13+ROW()/100000,"")
... A49: SKU-1048 | B49: Hydraulic Valve X | C49: Machinery Parts | D49: WH-East | E49: 96.82 | F49: 141.5 | G49: 142 | H49: 117 | I49: 485 | J49: 29 | K49: SUP-005 | L49: 12.6 | M49: 46204 | N49: =G49*E49 -> 13748.44 | O49: =IFERROR(G49/L49,"n/a") -> 11.269841 | P49: =IF(G49<=H49,"Reorder Now",IF(AND(ISNUMBER(O49),O49<14),"Low - Watch","OK")) -> Low - Watch | Q49: =IFERROR(INDEX(Suppliers!$B$2:$B$9,MATCH(K49,Suppliers!$A$2:$A$9,0)),"Unknown") -> Vertex Industrial Supply | R49: =IF(P49="Reorder Now",O49+ROW()/100000,"")

Sheet Purchase Orders
A1: Order ID | B1: SKU | C1: Supplier ID | D1: Order Date | E1: Expected Delivery | F1: Actual Delivery | G1: Qty Ordered | H1: Qty Received | I1: Status | J1: Unit Cost ($) | K1: Order Value ($) | L1: Delay (days) | M1: On-Time Flag | N1: Fulfillment Rate
A2: PO-2000 | B2: SKU-1045 | C2: SUP-005 | D2: 46279 | E2: 46304 | G2: 103 | H2: 0 | I2: Pending | J2: 385.82 | K2: =H2*J2 -> 0 | L2: =IF(F2="","",F2-E2) | M2: =IF(F2="","",IF(L2<=0,1,0)) | N2: =IF(G2=0,"",H2/G2) -> 0
A3: PO-2001 | B3: SKU-1008 | C3: SUP-004 | D3: 46226 | E3: 46237 | F3: 46243 | G3: 235 | H3: 235 | I3: Delivered | J3: 179.24 | K3: =H3*J3 -> 42121.4 | L3: =IF(F3="","",F3-E3) -> 6 | M3: =IF(F3="","",IF(L3<=0,1,0)) -> 0 | N3: =IF(G3=0,"",H3/G3) -> 1
A4: PO-2002 | B4: SKU-1005 | C4: SUP-006 | D4: 46211 | E4: 46243 | F4: 46241 | G4: 242 | H4: 242 | I4: Delivered | J4: 443.38 | K4: =H4*J4 -> 107297.96 | L4: =IF(F4="","",F4-E4) -> -2 | M4: =IF(F4="","",IF(L4<=0,1,0)) -> 1 | N4: =IF(G4=0,"",H4/G4) -> 1
A5: PO-2003 | B5: SKU-1007 | C5: SUP-004 | D5: 46192 | E5: 46199 | F5: 46210 | G5: 237 | H5: 237 | I5: Delivered | J5: 104.61 | K5: =H5*J5 -> 24792.57 | L5: =IF(F5="","",F5-E5) -> 11 | M5: =IF(F5="","",IF(L5<=0,1,0)) -> 0 | N5: =IF(G5=0,"",H5/G5) -> 1
A6: PO-2004 | B6: SKU-1010 | C6: SUP-001 | D6: 46193 | E6: 46231 | F6: 46231 | G6: 228 | H6: 228 | I6: Delivered | J6: 269.19 | K6: =H6*J6 -> 61375.32 | L6: =IF(F6="","",F6-E6) -> 0 | M6: =IF(F6="","",IF(L6<=0,1,0)) -> 1 | N6: =IF(G6=0,"",H6/G6) -> 1
A7: PO-2005 | B7: SKU-1035 | C7: SUP-002 | D7: 46280 | E7: 46325 | G7: 260 | H7: 0 | I7: Pending | J7: 165.17 | K7: =H7*J7 -> 0 | L7: =IF(F7="","",F7-E7) | M7: =IF(F7="","",IF(L7<=0,1,0)) | N7: =IF(G7=0,"",H7/G7) -> 0
A8: PO-2006 | B8: SKU-1038 | C8: SUP-006 | D8: 46150 | E8: 46171 | F8: 46169 | G8: 143 | H8: 143 | I8: Delivered | J8: 357.59 | K8: =H8*J8 -> 51135.37 | L8: =IF(F8="","",F8-E8) -> -2 | M8: =IF(F8="","",IF(L8<=0,1,0)) -> 1 | N8: =IF(G8=0,"",H8/G8) -> 1
A9: PO-2007 | B9: SKU-1029 | C9: SUP-004 | D9: 46144 | E9: 46160 | F9: 46170 | G9: 283 | H9: 283 | I9: Delivered | J9: 194.54 | K9: =H9*J9 -> 55054.82 | L9: =IF(F9="","",F9-E9) -> 10 | M9: =IF(F9="","",IF(L9<=0,1,0)) -> 0 | N9: =IF(G9=0,"",H9/G9) -> 1
A10: PO-2008 | B10: SKU-1002 | C10: SUP-007 | D10: 46208 | E10: 46245 | F10: 46248 | G10: 432 | H10: 432 | I10: Delivered | J10: 228.4 | K10: =H10*J10 -> 98668.8 | L10: =IF(F10="","",F10-E10) -> 3 | M10: =IF(F10="","",IF(L10<=0,1,0)) -> 0 | N10: =IF(G10=0,"",H10/G10) -> 1
A11: PO-2009 | B11: SKU-1017 | C11: SUP-002 | D11: 46169 | E11: 46175 | F11: 46175 | G11: 339 | H11: 339 | I11: Delivered | J11: 45.43 | K11: =H11*J11 -> 15400.77 | L11: =IF(F11="","",F11-E11) -> 0 | M11: =IF(F11="","",IF(L11<=0,1,0)) -> 1 | N11: =IF(G11=0,"",H11/G11) -> 1
A12: PO-2010 | B12: SKU-1001 | C12: SUP-002 | D12: 46214 | E12: 46251 | F12: 46253 | G12: 152 | H12: 152 | I12: Delivered | J12: 334.21 | K12: =H12*J12 -> 50799.92 | L12: =IF(F12="","",F12-E12) -> 2 | M12: =IF(F12="","",IF(L12<=0,1,0)) -> 0 | N12: =IF(G12=0,"",H12/G12) -> 1
A13: PO-2011 | B13: SKU-1036 | C13: SUP-007 | D13: 46276 | E13: 46321 | G13: 315 | H13: 0 | I13: Pending | J13: 148.13 | K13: =H13*J13 -> 0 | L13: =IF(F13="","",F13-E13) | M13: =IF(F13="","",IF(L13<=0,1,0)) | N13: =IF(G13=0,"",H13/G13) -> 0
A14: PO-2012 | B14: SKU-1032 | C14: SUP-006 | D14: 46196 | E14: 46216 | F14: 46218 | G14: 135 | H14: 135 | I14: Delivered | J14: 12.6 | K14: =H14*J14 -> 1701 | L14: =IF(F14="","",F14-E14) -> 2 | M14: =IF(F14="","",IF(L14<=0,1,0)) -> 0 | N14: =IF(G14=0,"",H14/G14) -> 1
A15: PO-2013 | B15: SKU-1016 | C15: SUP-008 | D15: 46160 | E15: 46171 | F15: 46170 | G15: 376 | H15: 376 | I15: Delivered | J15: 33.74 | K15: =H15*J15 -> 12686.24 | L15: =IF(F15="","",F15-E15) -> -1 | M15: =IF(F15="","",IF(L15<=0,1,0)) -> 1 | N15: =IF(G15=0,"",H15/G15) -> 1
A16: PO-2014 | B16: SKU-1028 | C16: SUP-002 | D16: 46272 | E16: 46282 | G16: 104 | H16: 0 | I16: Pending | J16: 74.39 | K16: =H16*J16 -> 0 | L16: =IF(F16="","",F16-E16) | M16: =IF(F16="","",IF(L16<=0,1,0)) | N16: =IF(G16=0,"",H16/G16) -> 0
A17: PO-2015 | B17: SKU-1018 | C17: SUP-004 | D17: 46160 | E17: 46192 | F17: 46190 | G17: 242 | H17: 242 | I17: Delivered | J17: 87.21 | K17: =H17*J17 -> 21104.82 | L17: =IF(F17="","",F17-E17) -> -2 | M17: =IF(F17="","",IF(L17<=0,1,0)) -> 1 | N17: =IF(G17=0,"",H17/G17) -> 1
A18: PO-2016 | B18: SKU-1048 | C18: SUP-005 | D18: 46219 | E18: 46248 | F18: 46260 | G18: 485 | H18: 485 | I18: Delivered | J18: 96.82 | K18: =H18*J18 -> 46957.7 | L18: =IF(F18="","",F18-E18) -> 12 | M18: =IF(F18="","",IF(L18<=0,1,0)) -> 0 | N18: =IF(G18=0,"",H18/G18) -> 1
A19: PO-2017 | B19: SKU-1031 | C19: SUP-004 | D19: 46152 | E19: 46185 | F19: 46194 | G19: 119 | H19: 119 | I19: Delivered | J19: 121.53 | K19: =H19*J19 -> 14462.07 | L19: =IF(F19="","",F19-E19) -> 9 | M19: =IF(F19="","",IF(L19<=0,1,0)) -> 0 | N19: =IF(G19=0,"",H19/G19) -> 1
A20: PO-2018 | B20: SKU-1013 | C20: SUP-002 | D20: 46157 | E20: 46191 | F20: 46189 | G20: 474 | H20: 474 | I20: Delivered | J20: 109.91 | K20: =H20*J20 -> 52097.34 | L20: =IF(F20="","",F20-E20) -> -2 | M20: =IF(F20="","",IF(L20<=0,1,0)) -> 1 | N20: =IF(G20=0,"",H20/G20) -> 1
A21: PO-2019 | B21: SKU-1009 | C21: SUP-002 | D21: 46152 | E21: 46186 | F21: 46184 | G21: 360 | H21: 360 | I21: Delivered | J21: 404.22 | K21: =H21*J21 -> 145519.2 | L21: =IF(F21="","",F21-E21) -> -2 | M21: =IF(F21="","",IF(L21<=0,1,0)) -> 1 | N21: =IF(G21=0,"",H21/G21) -> 1
A22: PO-2020 | B22: SKU-1009 | C22: SUP-002 | D22: 46245 | E22: 46279 | F22: 46287 | G22: 360 | H22: 281 | I22: Delivered | J22: 404.22 | K22: =H22*J22 -> 113585.82 | L22: =IF(F22="","",F22-E22) -> 8 | M22: =IF(F22="","",IF(L22<=0,1,0)) -> 0 | N22: =IF(G22=0,"",H22/G22) -> 0.78055556
A23: PO-2021 | B23: SKU-1031 | C23: SUP-004 | D23: 46194 | E23: 46227 | F23: 46225 | G23: 119 | H23: 119 | I23: Delivered | J23: 121.53 | K23: =H23*J23 -> 14462.07 | L23: =IF(F23="","",F23-E23) -> -2 | M23: =IF(F23="","",IF(L23<=0,1,0)) -> 1 | N23: =IF(G23=0,"",H23/G23) -> 1
A24: PO-2022 | B24: SKU-1008 | C24: SUP-004 | D24: 46098 | E24: 46109 | F24: 46107 | G24: 235 | H24: 235 | I24: Delivered | J24: 179.24 | K24: =H24*J24 -> 42121.4 | L24: =IF(F24="","",F24-E24) -> -2 | M24: =IF(F24="","",IF(L24<=0,1,0)) -> 1 | N24: =IF(G24=0,"",H24/G24) -> 1
A25: PO-2023 | B25: SKU-1010 | C25: SUP-001 | D25: 46120 | E25: 46158 | F25: 46163 | G25: 228 | H25: 228 | I25: Delivered | J25: 269.19 | K25: =H25*J25 -> 61375.32 | L25: =IF(F25="","",F25-E25) -> 5 | M25: =IF(F25="","",IF(L25<=0,1,0)) -> 0 | N25: =IF(G25=0,"",H25/G25) -> 1
A26: PO-2024 | B26: SKU-1036 | C26: SUP-007 | D26: 46277 | E26: 46322 | G26: 315 | H26: 0 | I26: Pending | J26: 148.13 | K26: =H26*J26 -> 0 | L26: =IF(F26="","",F26-E26) | M26: =IF(F26="","",IF(L26<=0,1,0)) | N26: =IF(G26=0,"",H26/G26) -> 0
A27: PO-2025 | B27: SKU-1015 | C27: SUP-004 | D27: 46280 | E27: 46297 | G27: 383 | H27: 0 | I27: Pending | J27: 113.06 | K27: =H27*J27 -> 0 | L27: =IF(F27="","",F27-E27) | M27: =IF(F27="","",IF(L27<=0,1,0)) | N27: =IF(G27=0,"",H27/G27) -> 0
A28: PO-2026 | B28: SKU-1020 | C28: SUP-008 | D28: 46232 | E28: 46262 | F28: 46267 | G28: 246 | H28: 240 | I28: Delivered | J28: 171.78 | K28: =H28*J28 -> 41227.2 | L28: =IF(F28="","",F28-E28) -> 5 | M28: =IF(F28="","",IF(L28<=0,1,0)) -> 0 | N28: =IF(G28=0,"",H28/G28) -> 0.97560976
A29: PO-2027 | B29: SKU-1007 | C29: SUP-004 | D29: 46277 | E29: 46284 | G29: 237 | H29: 0 | I29: Pending | J29: 104.61 | K29: =H29*J29 -> 0 | L29: =IF(F29="","",F29-E29) | M29: =IF(F29="","",IF(L29<=0,1,0)) | N29: =IF(G29=0,"",H29/G29) -> 0
A30: PO-2028 | B30: SKU-1006 | C30: SUP-005 | D30: 46122 | E30: 46149 | F30: 46149 | G30: 336 | H30: 279 | I30: Delivered | J30: 274.89 | K30: =H30*J30 -> 76694.31 | L30: =IF(F30="","",F30-E30) -> 0 | M30: =IF(F30="","",IF(L30<=0,1,0)) -> 1 | N30: =IF(G30=0,"",H30/G30) -> 0.83035714
A31: PO-2029 | B31: SKU-1039 | C31: SUP-008 | D31: 46202 | E31: 46209 | F31: 46207 | G31: 493 | H31: 493 | I31: Delivered | J31: 68.01 | K31: =H31*J31 -> 33528.93 | L31: =IF(F31="","",F31-E31) -> -2 | M31: =IF(F31="","",IF(L31<=0,1,0)) -> 1 | N31: =IF(G31=0,"",H31/G31) -> 1
A32: PO-2030 | B32: SKU-1030 | C32: SUP-003 | D32: 46100 | E32: 46104 | F32: 46103 | G32: 311 | H32: 311 | I32: Delivered | J32: 416.74 | K32: =H32*J32 -> 129606.14 | L32: =IF(F32="","",F32-E32) -> -1 | M32: =IF(F32="","",IF(L32<=0,1,0)) -> 1 | N32: =IF(G32=0,"",H32/G32) -> 1
A33: PO-2031 | B33: SKU-1043 | C33: SUP-006 | D33: 46132 | E33: 46156 | F33: 46156 | G33: 239 | H33: 239 | I33: Delivered | J33: 125.02 | K33: =H33*J33 -> 29879.78 | L33: =IF(F33="","",F33-E33) -> 0 | M33: =IF(F33="","",IF(L33<=0,1,0)) -> 1 | N33: =IF(G33=0,"",H33/G33) -> 1
A34: PO-2032 | B34: SKU-1018 | C34: SUP-004 | D34: 46118 | E34: 46150 | F34: 46148 | G34: 242 | H34: 242 | I34: Delivered | J34: 87.21 | K34: =H34*J34 -> 21104.82 | L34: =IF(F34="","",F34-E34) -> -2 | M34: =IF(F34="","",IF(L34<=0,1,0)) -> 1 | N34: =IF(G34=0,"",H34/G34) -> 1
A35: PO-2033 | B35: SKU-1037 | C35: SUP-006 | D35: 46155 | E35: 46195 | F35: 46194 | G35: 320 | H35: 320 | I35: Delivered | J35: 247.48 | K35: =H35*J35 -> 79193.6 | L35: =IF(F35="","",F35-E35) -> -1 | M35: =IF(F35="","",IF(L35<=0,1,0)) -> 1 | N35: =IF(G35=0,"",H35/G35) -> 1
A36: PO-2034 | B36: SKU-1018 | C36: SUP-004 | D36: 46210 | E36: 46242 | F36: 46241 | G36: 242 | H36: 199 | I36: Delivered | J36: 87.21 | K36: =H36*J36 -> 17354.79 | L36: =IF(F36="","",F36-E36) -> -1 | M36: =IF(F36="","",IF(L36<=0,1,0)) -> 1 | N36: =IF(G36=0,"",H36/G36) -> 0.82231405
A37: PO-2035 | B37: SKU-1021 | C37: SUP-001 | D37: 46236 | E37: 46249 | F37: 46247 | G37: 371 | H37: 371 | I37: Delivered | J37: 337.09 | K37: =H37*J37 -> 125060.39 | L37: =IF(F37="","",F37-E37) -> -2 | M37: =IF(F37="","",IF(L37<=0,1,0)) -> 1 | N37: =IF(G37=0,"",H37/G37) -> 1
A38: PO-2036 | B38: SKU-1037 | C38: SUP-006 | D38: 46232 | E38: 46272 | F38: 46283 | G38: 320 | H38: 320 | I38: Delivered | J38: 247.48 | K38: =H38*J38 -> 79193.6 | L38: =IF(F38="","",F38-E38) -> 11 | M38: =IF(F38="","",IF(L38<=0,1,0)) -> 0 | N38: =IF(G38=0,"",H38/G38) -> 1
A39: PO-2037 | B39: SKU-1012 | C39: SUP-001 | D39: 46202 | E39: 46236 | F39: 46235 | G39: 265 | H39: 265 | I39: Delivered | J39: 70.47 | K39: =H39*J39 -> 18674.55 | L39: =IF(F39="","",F39-E39) -> -1 | M39: =IF(F39="","",IF(L39<=0,1,0)) -> 1 | N39: =IF(G39=0,"",H39/G39) -> 1
A40: PO-2038 | B40: SKU-1038 | C40: SUP-006 | D40: 46193 | E40: 46214 | F40: 46213 | G40: 143 | H40: 143 | I40: Delivered | J40: 357.59 | K40: =H40*J40 -> 51135.37 | L40: =IF(F40="","",F40-E40) -> -1 | M40: =IF(F40="","",IF(L40<=0,1,0)) -> 1 | N40: =IF(G40=0,"",H40/G40) -> 1
...

Sheet ChartData
A1: Category | B1: Inventory Value ($) | D1: Stock Status | E1: SKU Count | G1: Supplier | H1: On-Time % (POs) | I1: Total Spend ($) | K1: Month | L1: PO Spend ($)
A2: Electronics | B2: =SUMIFS(Inventory!$N$2:$N$49,Inventory!$C$2:$C$49,A2) -> 253920.69 | D2: Reorder Now | E2: =COUNTIF(Inventory!$P$2:$P$49,D2) -> 12 | G2: =Suppliers!B2 -> Apex Components Ltd. | H2: =IFERROR(VALUE(Suppliers!J2),0) -> 0.8 | I2: =Suppliers!I2 -> 298024.36 | K2: 2026-03 | L2: =SUMPRODUCT((TEXT('Purchase Orders'!$D$2:$D$91,"yyyy-mm")=K2)*'Purchase Orders'!$K$2:$K$91) -> 408149.42
A3: Raw Materials | B3: =SUMIFS(Inventory!$N$2:$N$49,Inventory!$C$2:$C$49,A3) -> 387936.83 | D3: Low - Watch | E3: =COUNTIF(Inventory!$P$2:$P$49,D3) -> 10 | G3: =Suppliers!B3 -> Northline Materials Co. | H3: =IFERROR(VALUE(Suppliers!J3),0) -> 0.66666667 | I3: =Suppliers!I3 -> 590717.51 | K3: 2026-04 | L3: =SUMPRODUCT((TEXT('Purchase Orders'!$D$2:$D$91,"yyyy-mm")=K3)*'Purchase Orders'!$K$2:$K$91) -> 580153.92
A4: Packaging | B4: =SUMIFS(Inventory!$N$2:$N$49,Inventory!$C$2:$C$49,A4) -> 293669.64 | D4: OK | E4: =COUNTIF(Inventory!$P$2:$P$49,D4) -> 26 | G4: =Suppliers!B4 -> Global Pack Solutions | H4: =IFERROR(VALUE(Suppliers!J4),0) -> 0.88888889 | I4: =Suppliers!I4 -> 1080550.3 | K4: 2026-05 | L4: =SUMPRODUCT((TEXT('Purchase Orders'!$D$2:$D$91,"yyyy-mm")=K4)*'Purchase Orders'!$K$2:$K$91) -> 1333267.1
A5: Hardware | B5: =SUMIFS(Inventory!$N$2:$N$49,Inventory!$C$2:$C$49,A5) -> 288754.67 | G5: =Suppliers!B5 -> Sterling Hardware Inc. | H5: =IFERROR(VALUE(Suppliers!J5),0) -> 0.53333333 | I5: =Suppliers!I5 -> 409604.89 | K5: 2026-06 | L5: =SUMPRODUCT((TEXT('Purchase Orders'!$D$2:$D$91,"yyyy-mm")=K5)*'Purchase Orders'!$K$2:$K$91) -> 742766.68
A6: Consumables | B6: =SUMIFS(Inventory!$N$2:$N$49,Inventory!$C$2:$C$49,A6) -> 318556.24 | G6: =Suppliers!B6 -> Vertex Industrial Supply | H6: =IFERROR(VALUE(Suppliers!J6),0) -> 0.75 | I6: =Suppliers!I6 -> 555704.65 | K6: 2026-07 | L6: =SUMPRODUCT((TEXT('Purchase Orders'!$D$2:$D$91,"yyyy-mm")=K6)*'Purchase Orders'!$K$2:$K$91) -> 843098.57
A7: Machinery Parts | B7: =SUMIFS(Inventory!$N$2:$N$49,Inventory!$C$2:$C$49,A7) -> 268086.67 | G7: =Suppliers!B7 -> Meridian Parts Group | H7: =IFERROR(VALUE(Suppliers!J7),0) -> 0.55 | I7: =Suppliers!I7 -> 1199685.6 | K7: 2026-08 | L7: =SUMPRODUCT((TEXT('Purchase Orders'!$D$2:$D$91,"yyyy-mm")=K7)*'Purchase Orders'!$K$2:$K$91) -> 775473.03
G8: =Suppliers!B8 -> Prime Consumables Corp. | H8: =IFERROR(VALUE(Suppliers!J8),0) -> 0.4 | I8: =Suppliers!I8 -> 374040.15 | K8: 2026-09 | L8: =SUMPRODUCT((TEXT('Purchase Orders'!$D$2:$D$91,"yyyy-mm")=K8)*'Purchase Orders'!$K$2:$K$91) -> 93747.1
G9: =Suppliers!B9 -> Horizon Machinery Traders | H9: =IFERROR(VALUE(Suppliers!J9),0) -> 0.66666667 | I9: =Suppliers!I9 -> 268328.25
